Sep 01 01:55:34 ubuntu-s-1vcpu-1gb-sgp1-01 python[370432]: ERROR:root:Ошибка при запросе к Dispatcher API
Sep 01 01:55:34 ubuntu-s-1vcpu-1gb-sgp1-01 python[370432]: Traceback (most recent call last):
Sep 01 01:55:34 ubuntu-s-1vcpu-1gb-sgp1-01 python[370432]:   File "/home/uaft/uaft_project_50lite/.venv/lib/python3.10/site-packages/urllib3/connection.py", line 198, in _new_conn
Sep 01 01:55:34 ubuntu-s-1vcpu-1gb-sgp1-01 python[370432]:     sock = connection.create_connection(
Sep 01 01:55:34 ubuntu-s-1vcpu-1gb-sgp1-01 python[370432]:   File "/home/uaft/uaft_project_50lite/.venv/lib/python3.10/site-packages/urllib3/util/connection.py", line 85, in create_connection
Sep 01 01:55:34 ubuntu-s-1vcpu-1gb-sgp1-01 python[370432]:     raise err
Sep 01 01:55:34 ubuntu-s-1vcpu-1gb-sgp1-01 python[370432]:   File "/home/uaft/uaft_project_50lite/.venv/lib/python3.10/site-packages/urllib3/util/connection.py", line 73, in create_connection
Sep 01 01:55:34 ubuntu-s-1vcpu-1gb-sgp1-01 python[370432]:     sock.connect(sa)
Sep 01 01:55:34 ubuntu-s-1vcpu-1gb-sgp1-01 python[370432]: ConnectionRefusedError: [Errno 111] Connection refused
Sep 01 01:55:34 ubuntu-s-1vcpu-1gb-sgp1-01 python[370432]: The above exception was the direct cause of the following exception:
Sep 01 01:55:34 ubuntu-s-1vcpu-1gb-sgp1-01 python[370432]: Traceback (most recent call last):
Sep 01 01:55:34 ubuntu-s-1vcpu-1gb-sgp1-01 python[370432]:   File "/home/uaft/uaft_project_50lite/.venv/lib/python3.10/site-packages/urllib3/connectionpool.py", line 787, in urlopen
Sep 01 01:55:34 ubuntu-s-1vcpu-1gb-sgp1-01 python[370432]:     response = self._make_request(
Sep 01 01:55:34 ubuntu-s-1vcpu-1gb-sgp1-01 python[370432]:   File "/home/uaft/uaft_project_50lite/.venv/lib/python3.10/site-packages/urllib3/connectionpool.py", line 493, in _make_request
Sep 01 01:55:34 ubuntu-s-1vcpu-1gb-sgp1-01 python[370432]:     conn.request(
Sep 01 01:55:34 ubuntu-s-1vcpu-1gb-sgp1-01 python[370432]:   File "/home/uaft/uaft_project_50lite/.venv/lib/python3.10/site-packages/urllib3/connection.py", line 494, in request
Sep 01 01:55:34 ubuntu-s-1vcpu-1gb-sgp1-01 python[370432]:     self.endheaders()
Sep 01 01:55:34 ubuntu-s-1vcpu-1gb-sgp1-01 python[370432]:   File "/usr/lib/python3.10/http/client.py", line 1278, in endheaders
Sep 01 01:55:34 ubuntu-s-1vcpu-1gb-sgp1-01 python[370432]:     self._send_output(message_body, encode_chunked=encode_chunked)
Sep 01 01:55:34 ubuntu-s-1vcpu-1gb-sgp1-01 python[370432]:   File "/usr/lib/python3.10/http/client.py", line 1038, in _send_output
Sep 01 01:55:34 ubuntu-s-1vcpu-1gb-sgp1-01 python[370432]:     self.send(msg)
Sep 01 01:55:34 ubuntu-s-1vcpu-1gb-sgp1-01 python[370432]:   File "/usr/lib/python3.10/http/client.py", line 976, in send
Sep 01 01:55:34 ubuntu-s-1vcpu-1gb-sgp1-01 python[370432]:     self.connect()
Sep 01 01:55:34 ubuntu-s-1vcpu-1gb-sgp1-01 python[370432]:   File "/home/uaft/uaft_project_50lite/.venv/lib/python3.10/site-packages/urllib3/connection.py", line 325, in connect
Sep 01 01:55:34 ubuntu-s-1vcpu-1gb-sgp1-01 python[370432]:     self.sock = self._new_conn()
Sep 01 01:55:34 ubuntu-s-1vcpu-1gb-sgp1-01 python[370432]:   File "/home/uaft/uaft_project_50lite/.venv/lib/python3.10/site-packages/urllib3/connection.py", line 213, in _new_conn
Sep 01 01:55:34 ubuntu-s-1vcpu-1gb-sgp1-01 python[370432]:     raise NewConnectionError(
Sep 01 01:55:34 ubuntu-s-1vcpu-1gb-sgp1-01 python[370432]: urllib3.exceptions.NewConnectionError: <urllib3.connection.HTTPConnection object at 0x7f53ffb20790>: Failed to establish a new connection: [Errno 111] Connection refused
Sep 01 01:55:34 ubuntu-s-1vcpu-1gb-sgp1-01 python[370432]: The above exception was the direct cause of the following exception:
Sep 01 01:55:34 ubuntu-s-1vcpu-1gb-sgp1-01 python[370432]: Traceback (most recent call last):
Sep 01 01:55:34 ubuntu-s-1vcpu-1gb-sgp1-01 python[370432]:   File "/home/uaft/uaft_project_50lite/.venv/lib/python3.10/site-packages/requests/adapters.py", line 644, in send
Sep 01 01:55:34 ubuntu-s-1vcpu-1gb-sgp1-01 python[370432]:     resp = conn.urlopen(
Sep 01 01:55:34 ubuntu-s-1vcpu-1gb-sgp1-01 python[370432]:   File "/home/uaft/uaft_project_50lite/.venv/lib/python3.10/site-packages/urllib3/connectionpool.py", line 841, in urlopen
Sep 01 01:55:34 ubuntu-s-1vcpu-1gb-sgp1-01 python[370432]:     retries = retries.increment(
Sep 01 01:55:34 ubuntu-s-1vcpu-1gb-sgp1-01 python[370432]:   File "/home/uaft/uaft_project_50lite/.venv/lib/python3.10/site-packages/urllib3/util/retry.py", line 519, in increment
Sep 01 01:55:34 ubuntu-s-1vcpu-1gb-sgp1-01 python[370432]:     raise MaxRetryError(_pool, url, reason) from reason  # type: ignore[arg-type]
Sep 01 01:55:34 ubuntu-s-1vcpu-1gb-sgp1-01 python[370432]: urllib3.exceptions.MaxRetryError: HTTPConnectionPool(host='127.0.0.1', port=8000): Max retries exceeded with url: /answer (Caused by NewConnectionError('<urllib3.connection.HTTPConnection object at 0x7f53ffb20790>: Failed to establish a new connection: [Errno 111] Connection refused'))
Sep 01 01:55:34 ubuntu-s-1vcpu-1gb-sgp1-01 python[370432]: During handling of the above exception, another exception occurred:
Sep 01 01:55:34 ubuntu-s-1vcpu-1gb-sgp1-01 python[370432]: Traceback (most recent call last):
Sep 01 01:55:34 ubuntu-s-1vcpu-1gb-sgp1-01 python[370432]:   File "/home/uaft/uaft_project_50lite/tg_runner.py", line 26, in handle_message
Sep 01 01:55:34 ubuntu-s-1vcpu-1gb-sgp1-01 python[370432]:     r = requests.post(f"{DISPATCHER_URL}/answer", json={"text": user_text}, timeout=15)
Sep 01 01:55:34 ubuntu-s-1vcpu-1gb-sgp1-01 python[370432]:   File "/home/uaft/uaft_project_50lite/.venv/lib/python3.10/site-packages/requests/api.py", line 115, in post
Sep 01 01:55:34 ubuntu-s-1vcpu-1gb-sgp1-01 python[370432]:     return request("post", url, data=data, json=json, **kwargs)
Sep 01 01:55:34 ubuntu-s-1vcpu-1gb-sgp1-01 python[370432]:   File "/home/uaft/uaft_project_50lite/.venv/lib/python3.10/site-packages/requests/api.py", line 59, in request
Sep 01 01:55:34 ubuntu-s-1vcpu-1gb-sgp1-01 python[370432]:     return session.request(method=method, url=url, **kwargs)
Sep 01 01:55:34 ubuntu-s-1vcpu-1gb-sgp1-01 python[370432]:   File "/home/uaft/uaft_project_50lite/.venv/lib/python3.10/site-packages/requests/sessions.py", line 589, in request
Sep 01 01:55:34 ubuntu-s-1vcpu-1gb-sgp1-01 python[370432]:     resp = self.send(prep, **send_kwargs)
Sep 01 01:55:34 ubuntu-s-1vcpu-1gb-sgp1-01 python[370432]:   File "/home/uaft/uaft_project_50lite/.venv/lib/python3.10/site-packages/requests/sessions.py", line 703, in send
Sep 01 01:55:34 ubuntu-s-1vcpu-1gb-sgp1-01 python[370432]:     r = adapter.send(request, **kwargs)
Sep 01 01:55:34 ubuntu-s-1vcpu-1gb-sgp1-01 python[370432]:   File "/home/uaft/uaft_project_50lite/.venv/lib/python3.10/site-packages/requests/adapters.py", line 677, in send
Sep 01 01:55:34 ubuntu-s-1vcpu-1gb-sgp1-01 python[370432]:     raise ConnectionError(e, request=request)
Sep 01 01:55:34 ubuntu-s-1vcpu-1gb-sgp1-01 python[370432]: requests.exceptions.ConnectionError: HTTPConnectionPool(host='127.0.0.1', port=8000): Max retries exceeded with url: /answer (Caused by NewConnectionError('<urllib3.connection.HTTPConnection object at 0x7f53ffb20790>: Failed to establish a new connection: [Errno 111] Connection refused'))
