Sep 02 01:12:36 ubuntu-s-1vcpu-1gb-sgp1-01 python[419249]: ERROR:aiogram.dispatcher.dispatcher:Cause exception while getting updates.
Sep 02 01:12:36 ubuntu-s-1vcpu-1gb-sgp1-01 python[419249]: Traceback (most recent call last):
Sep 02 01:12:36 ubuntu-s-1vcpu-1gb-sgp1-01 python[419249]:   File "/home/uaft/uaft_project_50lite/.venv/lib/python3.10/site-packages/aiogram/dispatcher/dispatcher.py", line 381, in start_polling
Sep 02 01:12:36 ubuntu-s-1vcpu-1gb-sgp1-01 python[419249]:     updates = await self.bot.get_updates(
Sep 02 01:12:36 ubuntu-s-1vcpu-1gb-sgp1-01 python[419249]:   File "/home/uaft/uaft_project_50lite/.venv/lib/python3.10/site-packages/aiogram/bot/bot.py", line 110, in get_updates
Sep 02 01:12:36 ubuntu-s-1vcpu-1gb-sgp1-01 python[419249]:     result = await self.request(api.Methods.GET_UPDATES, payload)
Sep 02 01:12:36 ubuntu-s-1vcpu-1gb-sgp1-01 python[419249]:   File "/home/uaft/uaft_project_50lite/.venv/lib/python3.10/site-packages/aiogram/bot/base.py", line 236, in request
Sep 02 01:12:36 ubuntu-s-1vcpu-1gb-sgp1-01 python[419249]:     return await api.make_request(await self.get_session(), self.server, self.__token, method, data, files,
Sep 02 01:12:36 ubuntu-s-1vcpu-1gb-sgp1-01 python[419249]:   File "/home/uaft/uaft_project_50lite/.venv/lib/python3.10/site-packages/aiogram/bot/api.py", line 140, in make_request
Sep 02 01:12:36 ubuntu-s-1vcpu-1gb-sgp1-01 python[419249]:     return check_result(method, response.content_type, response.status, await response.text())
Sep 02 01:12:36 ubuntu-s-1vcpu-1gb-sgp1-01 python[419249]:   File "/home/uaft/uaft_project_50lite/.venv/lib/python3.10/site-packages/aiogram/bot/api.py", line 128, in check_result
Sep 02 01:12:36 ubuntu-s-1vcpu-1gb-sgp1-01 python[419249]:     raise exceptions.TelegramAPIError(description)
Sep 02 01:12:36 ubuntu-s-1vcpu-1gb-sgp1-01 python[419249]: aiogram.utils.exceptions.TelegramAPIError: Bad Gateway
Sep 02 01:12:41 ubuntu-s-1vcpu-1gb-sgp1-01 python[419249]: ERROR:aiogram.dispatcher.dispatcher:Cause exception while getting updates.
Sep 02 01:12:41 ubuntu-s-1vcpu-1gb-sgp1-01 python[419249]: Traceback (most recent call last):
Sep 02 01:12:41 ubuntu-s-1vcpu-1gb-sgp1-01 python[419249]:   File "/home/uaft/uaft_project_50lite/.venv/lib/python3.10/site-packages/aiogram/dispatcher/dispatcher.py", line 381, in start_polling
Sep 02 01:12:41 ubuntu-s-1vcpu-1gb-sgp1-01 python[419249]:     updates = await self.bot.get_updates(
Sep 02 01:12:41 ubuntu-s-1vcpu-1gb-sgp1-01 python[419249]:   File "/home/uaft/uaft_project_50lite/.venv/lib/python3.10/site-packages/aiogram/bot/bot.py", line 110, in get_updates
Sep 02 01:12:41 ubuntu-s-1vcpu-1gb-sgp1-01 python[419249]:     result = await self.request(api.Methods.GET_UPDATES, payload)
Sep 02 01:12:41 ubuntu-s-1vcpu-1gb-sgp1-01 python[419249]:   File "/home/uaft/uaft_project_50lite/.venv/lib/python3.10/site-packages/aiogram/bot/base.py", line 236, in request
Sep 02 01:12:41 ubuntu-s-1vcpu-1gb-sgp1-01 python[419249]:     return await api.make_request(await self.get_session(), self.server, self.__token, method, data, files,
Sep 02 01:12:41 ubuntu-s-1vcpu-1gb-sgp1-01 python[419249]:   File "/home/uaft/uaft_project_50lite/.venv/lib/python3.10/site-packages/aiogram/bot/api.py", line 140, in make_request
Sep 02 01:12:41 ubuntu-s-1vcpu-1gb-sgp1-01 python[419249]:     return check_result(method, response.content_type, response.status, await response.text())
Sep 02 01:12:41 ubuntu-s-1vcpu-1gb-sgp1-01 python[419249]:   File "/home/uaft/uaft_project_50lite/.venv/lib/python3.10/site-packages/aiogram/bot/api.py", line 128, in check_result
Sep 02 01:12:41 ubuntu-s-1vcpu-1gb-sgp1-01 python[419249]:     raise exceptions.TelegramAPIError(description)
Sep 02 01:12:41 ubuntu-s-1vcpu-1gb-sgp1-01 python[419249]: aiogram.utils.exceptions.TelegramAPIError: Bad Gateway
