Aug 29 07:50:18 ubuntu-s-1vcpu-1gb-sgp1-01 python3[148313]: Traceback (most recent call last):
Aug 29 07:50:18 ubuntu-s-1vcpu-1gb-sgp1-01 python3[148313]:   File "/home/uaft/uaft_project_50lite/tg_runner.py", line 43, in main
Aug 29 07:50:18 ubuntu-s-1vcpu-1gb-sgp1-01 python3[148313]:     resp.raise_for_status()
Aug 29 07:50:18 ubuntu-s-1vcpu-1gb-sgp1-01 python3[148313]:   File "/home/uaft/.local/lib/python3.10/site-packages/requests/models.py", line 1026, in raise_for_status
Aug 29 07:50:18 ubuntu-s-1vcpu-1gb-sgp1-01 python3[148313]:     raise HTTPError(http_error_msg, response=self)
Aug 29 07:50:18 ubuntu-s-1vcpu-1gb-sgp1-01 python3[148313]: requests.exceptions.HTTPError: 409 Client Error: Conflict for url: https://api.telegram.org/bot8075960342:AAElNMpncauiSVyWXYLTOB45BqCiBVLBmuc/getUpdates?timeout=25&offset=131648246
Aug 29 07:54:25 ubuntu-s-1vcpu-1gb-sgp1-01 python3[148313]: Traceback (most recent call last):
Aug 29 07:54:25 ubuntu-s-1vcpu-1gb-sgp1-01 python3[148313]:   File "/usr/lib/python3/dist-packages/urllib3/connection.py", line 169, in _new_conn
Aug 29 07:54:25 ubuntu-s-1vcpu-1gb-sgp1-01 python3[148313]:     conn = connection.create_connection(
Aug 29 07:54:25 ubuntu-s-1vcpu-1gb-sgp1-01 python3[148313]:   File "/usr/lib/python3/dist-packages/urllib3/util/connection.py", line 96, in create_connection
Aug 29 07:54:25 ubuntu-s-1vcpu-1gb-sgp1-01 python3[148313]:     raise err
Aug 29 07:54:25 ubuntu-s-1vcpu-1gb-sgp1-01 python3[148313]:   File "/usr/lib/python3/dist-packages/urllib3/util/connection.py", line 86, in create_connection
Aug 29 07:54:25 ubuntu-s-1vcpu-1gb-sgp1-01 python3[148313]:     sock.connect(sa)
Aug 29 07:54:25 ubuntu-s-1vcpu-1gb-sgp1-01 python3[148313]: OSError: [Errno 101] Network is unreachable
Aug 29 07:54:25 ubuntu-s-1vcpu-1gb-sgp1-01 python3[148313]: During handling of the above exception, another exception occurred:
Aug 29 07:54:25 ubuntu-s-1vcpu-1gb-sgp1-01 python3[148313]: Traceback (most recent call last):
Aug 29 07:54:25 ubuntu-s-1vcpu-1gb-sgp1-01 python3[148313]:   File "/usr/lib/python3/dist-packages/urllib3/connectionpool.py", line 700, in urlopen
Aug 29 07:54:25 ubuntu-s-1vcpu-1gb-sgp1-01 python3[148313]:     httplib_response = self._make_request(
Aug 29 07:54:25 ubuntu-s-1vcpu-1gb-sgp1-01 python3[148313]:   File "/usr/lib/python3/dist-packages/urllib3/connectionpool.py", line 383, in _make_request
Aug 29 07:54:25 ubuntu-s-1vcpu-1gb-sgp1-01 python3[148313]:     self._validate_conn(conn)
Aug 29 07:54:25 ubuntu-s-1vcpu-1gb-sgp1-01 python3[148313]:   File "/usr/lib/python3/dist-packages/urllib3/connectionpool.py", line 1017, in _validate_conn
Aug 29 07:54:25 ubuntu-s-1vcpu-1gb-sgp1-01 python3[148313]:     conn.connect()
Aug 29 07:54:25 ubuntu-s-1vcpu-1gb-sgp1-01 python3[148313]:   File "/usr/lib/python3/dist-packages/urllib3/connection.py", line 353, in connect
Aug 29 07:54:25 ubuntu-s-1vcpu-1gb-sgp1-01 python3[148313]:     conn = self._new_conn()
Aug 29 07:54:25 ubuntu-s-1vcpu-1gb-sgp1-01 python3[148313]:   File "/usr/lib/python3/dist-packages/urllib3/connection.py", line 181, in _new_conn
Aug 29 07:54:25 ubuntu-s-1vcpu-1gb-sgp1-01 python3[148313]:     raise NewConnectionError(
Aug 29 07:54:25 ubuntu-s-1vcpu-1gb-sgp1-01 python3[148313]: urllib3.exceptions.NewConnectionError: <urllib3.connection.HTTPSConnection object at 0x7ff5d5fdb0d0>: Failed to establish a new connection: [Errno 101] Network is unreachable
Aug 29 07:54:25 ubuntu-s-1vcpu-1gb-sgp1-01 python3[148313]: During handling of the above exception, another exception occurred:
Aug 29 07:54:25 ubuntu-s-1vcpu-1gb-sgp1-01 python3[148313]: Traceback (most recent call last):
Aug 29 07:54:25 ubuntu-s-1vcpu-1gb-sgp1-01 python3[148313]:   File "/home/uaft/.local/lib/python3.10/site-packages/requests/adapters.py", line 644, in send
Aug 29 07:54:25 ubuntu-s-1vcpu-1gb-sgp1-01 python3[148313]:     resp = conn.urlopen(
Aug 29 07:54:25 ubuntu-s-1vcpu-1gb-sgp1-01 python3[148313]:   File "/usr/lib/python3/dist-packages/urllib3/connectionpool.py", line 756, in urlopen
Aug 29 07:54:25 ubuntu-s-1vcpu-1gb-sgp1-01 python3[148313]:     retries = retries.increment(
Aug 29 07:54:25 ubuntu-s-1vcpu-1gb-sgp1-01 python3[148313]:   File "/usr/lib/python3/dist-packages/urllib3/util/retry.py", line 576, in increment
Aug 29 07:54:25 ubuntu-s-1vcpu-1gb-sgp1-01 python3[148313]:     raise MaxRetryError(_pool, url, error or ResponseError(cause))
Aug 29 07:54:25 ubuntu-s-1vcpu-1gb-sgp1-01 python3[148313]: urllib3.exceptions.MaxRetryError: HTTPSConnectionPool(host='api.telegram.org', port=443): Max retries exceeded with url: /bot8075960342:AAElNMpncauiSVyWXYLTOB45BqCiBVLBmuc/getUpdates?timeout=25&offset=131648246 (Caused by NewConnectionError('<urllib3.connection.HTTPSConnection object at 0x7ff5d5fdb0d0>: Failed to establish a new connection: [Errno 101] Network is unreachable'))
Aug 29 07:54:25 ubuntu-s-1vcpu-1gb-sgp1-01 python3[148313]: During handling of the above exception, another exception occurred:
Aug 29 07:54:25 ubuntu-s-1vcpu-1gb-sgp1-01 python3[148313]: Traceback (most recent call last):
Aug 29 07:54:25 ubuntu-s-1vcpu-1gb-sgp1-01 python3[148313]:   File "/home/uaft/uaft_project_50lite/tg_runner.py", line 42, in main
Aug 29 07:54:25 ubuntu-s-1vcpu-1gb-sgp1-01 python3[148313]:     resp = requests.get(f"{BASE}/getUpdates", params={"timeout": TIMEOUT, "offset": OFFSET}, timeout=TIMEOUT+5)
Aug 29 07:54:25 ubuntu-s-1vcpu-1gb-sgp1-01 python3[148313]:   File "/home/uaft/.local/lib/python3.10/site-packages/requests/api.py", line 73, in get
Aug 29 07:54:25 ubuntu-s-1vcpu-1gb-sgp1-01 python3[148313]:     return request("get", url, params=params, **kwargs)
Aug 29 07:54:25 ubuntu-s-1vcpu-1gb-sgp1-01 python3[148313]:   File "/home/uaft/.local/lib/python3.10/site-packages/requests/api.py", line 59, in request
Aug 29 07:54:25 ubuntu-s-1vcpu-1gb-sgp1-01 python3[148313]:     return session.request(method=method, url=url, **kwargs)
Aug 29 07:54:25 ubuntu-s-1vcpu-1gb-sgp1-01 python3[148313]:   File "/home/uaft/.local/lib/python3.10/site-packages/requests/sessions.py", line 589, in request
Aug 29 07:54:25 ubuntu-s-1vcpu-1gb-sgp1-01 python3[148313]:     resp = self.send(prep, **send_kwargs)
Aug 29 07:54:25 ubuntu-s-1vcpu-1gb-sgp1-01 python3[148313]:   File "/home/uaft/.local/lib/python3.10/site-packages/requests/sessions.py", line 703, in send
Aug 29 07:54:25 ubuntu-s-1vcpu-1gb-sgp1-01 python3[148313]:     r = adapter.send(request, **kwargs)
Aug 29 07:54:25 ubuntu-s-1vcpu-1gb-sgp1-01 python3[148313]:   File "/home/uaft/.local/lib/python3.10/site-packages/requests/adapters.py", line 677, in send
Aug 29 07:54:25 ubuntu-s-1vcpu-1gb-sgp1-01 python3[148313]:     raise ConnectionError(e, request=request)
Aug 29 07:54:25 ubuntu-s-1vcpu-1gb-sgp1-01 python3[148313]: requests.exceptions.ConnectionError: HTTPSConnectionPool(host='api.telegram.org', port=443): Max retries exceeded with url: /bot8075960342:AAElNMpncauiSVyWXYLTOB45BqCiBVLBmuc/getUpdates?timeout=25&offset=131648246 (Caused by NewConnectionError('<urllib3.connection.HTTPSConnection object at 0x7ff5d5fdb0d0>: Failed to establish a new connection: [Errno 101] Network is unreachable'))
